Traceback (most recent call last):
  File "/srv/conda/envs/notebook/lib/python3.8/site-packages/jupyter_cache/executors/utils.py", line 51, in single_nb_execution
    executenb(
  File "/srv/conda/envs/notebook/lib/python3.8/site-packages/nbclient/client.py", line 1107, in execute
    return NotebookClient(nb=nb, resources=resources, km=km, **kwargs).execute()
  File "/srv/conda/envs/notebook/lib/python3.8/site-packages/nbclient/util.py", line 74, in wrapped
    return just_run(coro(*args, **kwargs))
  File "/srv/conda/envs/notebook/lib/python3.8/site-packages/nbclient/util.py", line 53, in just_run
    return loop.run_until_complete(coro)
  File "/srv/conda/envs/notebook/lib/python3.8/asyncio/base_events.py", line 616, in run_until_complete
    return future.result()
  File "/srv/conda/envs/notebook/lib/python3.8/site-packages/nbclient/client.py", line 553, in async_execute
    await self.async_execute_cell(
  File "/srv/conda/envs/notebook/lib/python3.8/site-packages/nbclient/client.py", line 852, in async_execute_cell
    self._check_raise_for_error(cell, exec_reply)
  File "/srv/conda/envs/notebook/lib/python3.8/site-packages/nbclient/client.py", line 760, in _check_raise_for_error
    raise CellExecutionError.from_cell_and_msg(cell, exec_reply_content)
nbclient.exceptions.CellExecutionError: An error occurred while executing the following cell:
------------------
unw_rast = rio.open(unw)
meta_data = unw_rast.profile
print(meta_data)
------------------

[0;31m---------------------------------------------------------------------------[0m
[0;31mNameError[0m                                 Traceback (most recent call last)
[0;32m<ipython-input-4-07f2e2bd6e91>[0m in [0;36m<module>[0;34m[0m
[0;32m----> 1[0;31m [0munw_rast[0m [0;34m=[0m [0mrio[0m[0;34m.[0m[0mopen[0m[0;34m([0m[0munw[0m[0;34m)[0m[0;34m[0m[0;34m[0m[0m
[0m[1;32m      2[0m [0mmeta_data[0m [0;34m=[0m [0munw_rast[0m[0;34m.[0m[0mprofile[0m[0;34m[0m[0;34m[0m[0m
[1;32m      3[0m [0mprint[0m[0;34m([0m[0mmeta_data[0m[0;34m)[0m[0;34m[0m[0;34m[0m[0m

[0;31mNameError[0m: name 'unw' is not defined
NameError: name 'unw' is not defined

